<?xml version="1.0" encoding="UTF-8"?>
<testng-results skipped="0" failed="1" ignored="0" total="1" passed="0">
  <reporter-output>
  </reporter-output>
  <suite name="Default suite" duration-ms="28929" started-at="2018-03-26T04:26:01Z" finished-at="2018-03-26T04:26:30Z">
    <groups>
    </groups>
    <test name="Default test" duration-ms="28929" started-at="2018-03-26T04:26:01Z" finished-at="2018-03-26T04:26:30Z">
      <class name="Academy.validateTitle">
        <test-method status="PASS" signature="initialize()[pri:0, instance:Academy.validateTitle@672872e1]" name="initialize" is-config="true" duration-ms="26518" started-at="2018-03-26T09:56:01Z" finished-at="2018-03-26T09:56:28Z">
          <reporter-output>
          </reporter-output>
        </test-method> <!-- initialize -->
        <test-method status="FAIL" signature="validateAppTitle()[pri:0, instance:Academy.validateTitle@672872e1]" name="validateAppTitle" duration-ms="79" started-at="2018-03-26T09:56:28Z" finished-at="2018-03-26T09:56:28Z">
          <exception class="java.lang.AssertionError">
            <message>
              <![CDATA[expected [FEATURED CO123URSES] but found [FEATURED COURSES]]]>
            </message>
            <full-stacktrace>
              <![CDATA[java.lang.AssertionError: expected [FEATURED CO123URSES] but found [FEATURED COURSES]
	at org.testng.Assert.fail(Assert.java:93)
	at org.testng.Assert.failNotEquals(Assert.java:512)
	at org.testng.Assert.assertEqualsImpl(Assert.java:134)
	at org.testng.Assert.assertEquals(Assert.java:115)
	at org.testng.Assert.assertEquals(Assert.java:189)
	at org.testng.Assert.assertEquals(Assert.java:199)
	at Academy.validateTitle.validateAppTitle(validateTitle.java:41)
	at sun.reflect.NativeMethodAccessorImpl.invoke0(Native Method)
	at sun.reflect.NativeMethodAccessorImpl.invoke(Unknown Source)
	at sun.reflect.DelegatingMethodAccessorImpl.invoke(Unknown Source)
	at java.lang.reflect.Method.invoke(Unknown Source)
	at org.testng.internal.MethodInvocationHelper.invokeMethod(MethodInvocationHelper.java:108)
	at org.testng.internal.Invoker.invokeMethod(Invoker.java:669)
	at org.testng.internal.Invoker.invokeTestMethod(Invoker.java:877)
	at org.testng.internal.Invoker.invokeTestMethods(Invoker.java:1201)
	at org.testng.internal.TestMethodWorker.invokeTestMethods(TestMethodWorker.java:125)
	at org.testng.internal.TestMethodWorker.run(TestMethodWorker.java:109)
	at org.testng.TestRunner.privateRun(TestRunner.java:776)
	at org.testng.TestRunner.run(TestRunner.java:634)
	at org.testng.SuiteRunner.runTest(SuiteRunner.java:425)
	at org.testng.SuiteRunner.runSequentially(SuiteRunner.java:420)
	at org.testng.SuiteRunner.privateRun(SuiteRunner.java:385)
	at org.testng.SuiteRunner.run(SuiteRunner.java:334)
	at org.testng.SuiteRunnerWorker.runSuite(SuiteRunnerWorker.java:52)
	at org.testng.SuiteRunnerWorker.run(SuiteRunnerWorker.java:86)
	at org.testng.TestNG.runSuitesSequentially(TestNG.java:1318)
	at org.testng.TestNG.runSuitesLocally(TestNG.java:1243)
	at org.testng.TestNG.runSuites(TestNG.java:1161)
	at org.testng.TestNG.run(TestNG.java:1129)
	at org.testng.remote.AbstractRemoteTestNG.run(AbstractRemoteTestNG.java:114)
	at org.testng.remote.RemoteTestNG.initAndRun(RemoteTestNG.java:251)
	at org.testng.remote.RemoteTestNG.main(RemoteTestNG.java:77)
]]>
            </full-stacktrace>
          </exception> <!-- java.lang.AssertionError -->
          <reporter-output>
          </reporter-output>
        </test-method> <!-- validateAppTitle -->
        <test-method status="PASS" signature="teardown()[pri:0, instance:Academy.validateTitle@672872e1]" name="teardown" is-config="true" duration-ms="2308" started-at="2018-03-26T09:56:28Z" finished-at="2018-03-26T09:56:30Z">
          <reporter-output>
          </reporter-output>
        </test-method> <!-- teardown -->
      </class> <!-- Academy.validateTitle -->
    </test> <!-- Default test -->
  </suite> <!-- Default suite -->
</testng-results>
